Workbook

Sheet Overview
A1: BubbleSort
A2: AVERAGE
A3: Number List Size | B3: 10 | C3: 100 | D3: 1000 | E3: 10000 | F3: 100000 | G3: 1000000
A4: Miliseconds (BubbleSort) | B4: 2.3 | C4: 0.7 | D4: 48 | E4: 392.5 | F4: 55806 | G4: 4074918.6
A5: Swaps (BubbleSort) | B5: 21.1 | C5: 2465.4 | D5: 2698921.3 | E5: 22747974 | F5: 2.4702546e+09 | G5: 2.4744433e+11
A6: Comparisons (BubbleSort) | B6: 49990.5 | C6: 5003955 | D6: 500444550 | E6: 5000044495500 | F6: 4999950000 | G6: 49999995000000
A8: SelectionSort
A9: AVERAGE
A10: Number List Size | B10: 10 | C10: 100 | D10: 1000 | E10: 10000 | F10: 100000 | G10: 1000000
A11: Miliseconds (SelectionSort) | B11: 0.8 | C11: 1.8 | D11: 33.4 | E11: 467.1 | F11: 62800.4 | G11: 1450258.6
A12: Swaps (SelectionSort) | B12: 9 | C12: 99 | D12: 999 | E12: 9999 | F12: 99999 | G12: 999999
A13: Comparisons (SelectionSort) | B13: 49990.5 | C13: 5003955 | D13: 500444550 | E13: 50044945500 | F13: 4999950000 | G13: 499999500000
A15: InsertionSort
A16: AVERAGE
A17: Number List Size (InsertionSort) | B17: 10 | C17: 100 | D17: 1000 | E17: 10000 | F17: 100000 | G17: 1000000
A18: Miliseconds (InsertionSort) | B18: 1.2 | C18: 0.3 | D18: 42.1 | E18: 777.7 | F18: 34517.1 | G18: 3076937.1
A19: Swaps (InsertionSort) | B19: 21.1 | C19: 2465.5 | D19: 2698921.3 | E19: 22747974 | F19: 2.4702546e+09 | G19: 2.4750073e+11
A20: Comparisons (InsertionSort) | B20: 25029.2 | C20: 2488980.9 | D20: 2.4832865e+08 | E20: 2.4762037e+10 | F20: 2.4767323e+09 | G20: 2.1998311e+11
A22: MergeSort
A23: AVERAGE
A24: Number List Size | B24: 10 | C24: 100 | D24: 1000 | E24: 10000 | F24: 100000 | G24: 1000000
A25: Miliseconds (MergeSort) | B25: 1.8 | C25: 0.5 | D25: 5.4 | E25: 19.6 | F25: 131.1 | G25: 828.8
A26: Swaps (MergeSort) | B26: 455 | C26: 281.2 | D26: 4391.6 | E26: 61355.6 | F26: 776437.3 | G26: 9395200.6
A27: Comparisons (MergeSort) | B27: 894.1 | C27: 12530.5 | D27: 161459.7 | E27: 1975890.2 | F27: 1536354.4 | G27: 18674383
A29: QuickSort
A30: AVERAGE
A31: Number List Size | B31: 10 | C31: 100 | D31: 1000 | E31: 10000 | F31: 100000 | G31: 1000000
A32: Miliseconds (QuickSort) | B32: 0 | C32: 0.3 | D32: 2.3 | E32: 7.1 | F32: 32.5 | G32: 199
A33: Swaps (QuickSort) | B33: 18.2 | C33: 403.3 | D33: 6169 | E33: 86020.4 | F33: 1108697.3 | G33: 13489906
A34: Comparisons (QuickSort) | B34: 1171.1 | C34: 17243.5 | D34: 217247.5 | E34: 2856761.2 | F34: 2144724.4 | G34: 25978646
A36: HeapSort
A37: AVERAGE
A38: Number List Size | B38: 10 | C38: 100 | D38: 1000 | E38: 10000 | F38: 100000 | G38: 1000000
A39: Miliseconds (HeapSort) | B39: 0 | C39: 0.8 | D39: 1.8 | E39: 9.8 | F39: 58.2 | G39: 341.6
A40: Swaps (HeapSort) | B40: 27.8 | C40: 581.7 | D40: 20658.3 | E40: 269727 | F40: 3326971.7 | G40: 19073786
A41: Comparisons (HeapSort) | B41: 1975.6 | C41: 27036 | D41: 342833.2 | E41: 4147652.8 | F41: 3254772.8 | G41: 39147573

Sheet BubbleSort
A1: BubbleSort Analysis Tables | I1: AVERAGE
I2: Number List Size | J2: 10 | K2: 100 | L2: 1000 | M2: 10000 | N2: 100000 | O2: 1000000
A3: Trial 1 | I3: Miliseconds | J3: =AVERAGE(BubbleSort!B5,BubbleSort!B11,BubbleSort!B17,BubbleSort!B23,BubbleSort!B29,BubbleSort!B35,BubbleSort!B41,BubbleSort!B47,BubbleSort!B53,BubbleSort!B59) -> 2.3 | K3: =AVERAGE(BubbleSort!C5,BubbleSort!C11,BubbleSort!C17,BubbleSort!C23,BubbleSort!C29,BubbleSort!C35,BubbleSort!C41,BubbleSort!C47,BubbleSort!C53,BubbleSort!C59) -> 0.7 | L3: =AVERAGE(BubbleSort!D5,BubbleSort!D11,BubbleSort!D17,BubbleSort!D23,BubbleSort!D29,BubbleSort!D35,BubbleSort!D41,BubbleSort!D47,BubbleSort!D53,BubbleSort!D59) -> 48 | M3: =AVERAGE(BubbleSort!E5,BubbleSort!E11,BubbleSort!E17,BubbleSort!E23,BubbleSort!E29,BubbleSort!E35,BubbleSort!E41,BubbleSort!E47,BubbleSort!E53,BubbleSort!E59) -> 392.5 | N3: =AVERAGE(BubbleSort!F5,BubbleSort!F11,BubbleSort!F17,BubbleSort!F23,BubbleSort!F29,BubbleSort!F35,BubbleSort!F41,BubbleSort!F47,BubbleSort!F53,BubbleSort!F59) -> 55806 | O3: =AVERAGE(BubbleSort!G5,BubbleSort!G11,BubbleSort!G17,BubbleSort!G23,BubbleSort!G29,BubbleSort!G35,BubbleSort!G41,BubbleSort!G47,BubbleSort!G53,BubbleSort!G59) -> 4074918.6
A4: Number List Size | B4: 10 | C4: 100 | D4: 1000 | E4: 10000 | F4: 100000 | G4: 1000000 | I4: Swaps | J4: =AVERAGE(BubbleSort!B6,BubbleSort!B12,BubbleSort!B18,BubbleSort!B24,BubbleSort!B30,BubbleSort!B36,BubbleSort!B42,BubbleSort!B48,BubbleSort!B54,BubbleSort!B60) -> 21.1 | K4: =AVERAGE(BubbleSort!C6,BubbleSort!C12,BubbleSort!C18,BubbleSort!C24,BubbleSort!C30,BubbleSort!C36,BubbleSort!C42,BubbleSort!C48,BubbleSort!C54,BubbleSort!C60) -> 2465.4 | L4: =AVERAGE(BubbleSort!D6,BubbleSort!D12,BubbleSort!D18,BubbleSort!D24,BubbleSort!D30,BubbleSort!D36,BubbleSort!D42,BubbleSort!D48,BubbleSort!D54,BubbleSort!D60) -> 2698921.3 | M4: =AVERAGE(BubbleSort!E6,BubbleSort!E12,BubbleSort!E18,BubbleSort!E24,BubbleSort!E30,BubbleSort!E36,BubbleSort!E42,BubbleSort!E48,BubbleSort!E54,BubbleSort!E60) -> 22747974 | N4: =AVERAGE(BubbleSort!F6,BubbleSort!F12,BubbleSort!F18,BubbleSort!F24,BubbleSort!F30,BubbleSort!F36,BubbleSort!F42,BubbleSort!F48,BubbleSort!F54,BubbleSort!F60) -> 2.4702546e+09 | O4: =AVERAGE(BubbleSort!G6,BubbleSort!G12,BubbleSort!G18,BubbleSort!G24,BubbleSort!G30,BubbleSort!G36,BubbleSort!G42,BubbleSort!G48,BubbleSort!G54,BubbleSort!G60) -> 2.4744433e+11
A5: Miliseconds | B5: 1 | C5: 0 | D5: 22 | E5: 186 | F5: 33075 | G5: 3147574 | I5: Comparisons | J5: =AVERAGE(BubbleSort!D7,BubbleSort!B13,BubbleSort!B19,BubbleSort!B25,BubbleSort!B31,BubbleSort!B37,BubbleSort!B43,BubbleSort!B49,BubbleSort!B55,BubbleSort!B61) -> 49990.5 | K5: =AVERAGE(BubbleSort!E7,BubbleSort!C13,BubbleSort!C19,BubbleSort!C25,BubbleSort!C31,BubbleSort!C37,BubbleSort!C43,BubbleSort!C49,BubbleSort!C55,BubbleSort!C61) -> 5003955 | L5: =AVERAGE(BubbleSort!F7,BubbleSort!D13,BubbleSort!D19,BubbleSort!D25,BubbleSort!D31,BubbleSort!D37,BubbleSort!D43,BubbleSort!D49,BubbleSort!D55,BubbleSort!D61) -> 500444550 | M5: =AVERAGE(BubbleSort!G7,BubbleSort!E13,BubbleSort!E19,BubbleSort!E25,BubbleSort!E31,BubbleSort!E37,BubbleSort!E43,BubbleSort!E49,BubbleSort!E55,BubbleSort!E61) -> 5000044495500 | N5: =AVERAGE(F7,BubbleSort!F13,BubbleSort!F19,BubbleSort!F25,BubbleSort!F31,BubbleSort!F37,BubbleSort!F43,BubbleSort!F49,BubbleSort!F55,BubbleSort!F61) -> 4999950000 | O5: =AVERAGE(SelectionSort!A7,BubbleSort!G13,BubbleSort!G19,BubbleSort!G25,BubbleSort!G31,BubbleSort!G37,BubbleSort!G43,BubbleSort!G49,BubbleSort!G55,BubbleSort!G61) -> 49999995000000
A6: Swaps | B6: 20 | C6: 2534 | D6: 252360 | E6: 24576245 | F6: 2463898384 | G6: 247273286303
A7: Comparisons | B7: 45 | C7: 4950 | D7: 499500 | E7: 49995000 | F7: 4999950000 | G7: 49999995000000
A9: Trial 2
A10: Number List Size | B10: 10 | C10: 100 | D10: 1000 | E10: 10000 | F10: 100000 | G10: 1000000
A11: Miliseconds | B11: 0 | C11: 1 | D11: 25 | E11: 224 | F11: 31036 | G11: 3284264
A12: Swaps | B12: 16 | C12: 2575 | D12: 24745920 | E12: 4745920 | F12: 2470485380 | G12: 247599642830
A13: Comparisons | B13: 45 | C13: 4950 | D13: 499500 | E13: 49995000 | F13: 4999950000 | G13: 49999995000000
A15: Trial 3
A16: Number List Size | B16: 10 | C16: 100 | D16: 1000 | E16: 10000 | F16: 100000 | G16: 1000000
A17: Miliseconds | B17: 2 | C17: 1 | D17: 69 | E17: 462 | F17: 56051 | G17: 3158935
A18: Swaps | B18: 29 | C18: 2217 | D18: 251647 | E18: 24857018 | F18: 2478976078 | G18: 247470586576
A19: Comparisons | B19: 45 | C19: 4950 | D19: 499500 | E19: 49995000 | F19: 4999950000 | G19: 49999995000000
A21: Trial 4
A22: Number List Size | B22: 10 | C22: 100 | D22: 1000 | E22: 10000 | F22: 100000 | G22: 1000000
A23: Miliseconds | B23: 1 | C23: 0 | D23: 109 | E23: 843 | F23: 76640 | G23: 3219267
A24: Swaps | B24: 14 | C24: 2553 | D24: 253151 | E24: 24795077 | F24: 2475410164 | G24: 247363571736 | I24: WORST RUN (Trial 3)
A25: Comparisons | B25: 45 | C25: 4950 | D25: 499500 | E25: 49995000 | F25: 4999950000 | G25: 49999995000000 | I25: Number List Size | J25: 10 | K25: 100 | L25: 1000 | M25: 10000 | N25: 100000 | O25: 1000000
I26: Miliseconds | J26: 2 | K26: 1 | L26: 69 | M26: 462 | N26: 56051 | O26: 3158935
A27: Trial 5 | I27: Swaps | J27: 29 | K27: 2217 | L27: 251647 | M27: 24857018 | N27: 2478976078 | O27: 247470586576
A28: Number List Size | B28: 10 | C28: 100 | D28: 1000 | E28: 10000 | F28: 100000 | G28: 1000000 | I28: Comparisons | J28: 45 | K28: 4950 | L28: 499500 | M28: 49995000 | N28: 4999950000 | O28: 49999995000000
A29: Miliseconds | B29: 1 | C29: 0 | D29: 64 | E29: 444 | F29: 76659 | G29: 3254550
A30: Swaps | B30: 13 | C30: 2459 | D30: 248725 | E30: 24906899 | F30: 2475256811 | G30: 247561366440
A31: Comparisons | B31: 45 | C31: 4950 | D31: 499500 | E31: 49995000 | F31: 4999950000 | G31: 49999995000000
A33: Trial 6
A34: Number List Size | B34: 10 | C34: 100 | D34: 1000 | E34: 10000 | F34: 100000 | G34: 1000000
A35: Miliseconds | B35: 1 | C35: 0 | D35: 22 | E35: 167 | F35: 30005 | G35: 3126709
A36: Swaps | B36: 18 | C36: 2218 | D36: 247729 | E36: 24419431 | F36: 2461791067 | G36: 247291479589
A37: Comparisons | B37: 45 | C37: 4950 | D37: 499500 | E37: 49995000 | F37: 4999950000 | G37: 49999995000000
A39: Trial 7
A40: Number List Size | B40: 10 | C40: 100 | D40: 1000 | E40: 10000 | F40: 100000 | G40: 1000000
A41: Miliseconds | B41: 0 | C41: 0 | D41: 22 | E41: 244 | F41: 37623 | G41: 7015290
A42: Swaps | B42: 31 | C42: 2476 | D42: 243002 | E42: 24736817 | F42: 2468310878 | G42: 247499748700
A43: Comparisons | B43: 45 | C43: 4950 | D43: 499500 | E43: 49995000 | F43: 4999950000 | G43: 49999995000000
A45: Trial 8
A46: Number List Size | B46: 10 | C46: 100 | D46: 1000 | E46: 10000 | F46: 100000 | G46: 1000000
...

Sheet SelectionSort
A1: SelectionSort Analysis Tables | I1: AVERAGE
I2: Number List Size | J2: 10 | K2: 100 | L2: 1000 | M2: 10000 | N2: 100000 | O2: 1000000
A3: Trial 1 | I3: Miliseconds | J3: =AVERAGE(B5,B11,B17,B23,B29,B35,B41,B47,B53,B59) -> 0.8 | K3: =AVERAGE(C5,C11,C17,C23,C29,C35,C41,C47,C53,C59) -> 1.8 | L3: =AVERAGE(D5,D11,D17,D23,D29,D35,D41,D47,D53,D59) -> 33.4 | M3: =AVERAGE(E5,E11,E17,E23,E29,E35,E41,E47,E53,E59) -> 467.1 | N3: =AVERAGE(F5,F11,F17,F23,F29,F35,F41,F47,F53,F59) -> 62800.4 | O3: =AVERAGE(G5,G11,G17,G23,G29,G35,G41,G47,G53,G59) -> 1450258.6
A4: Number List Size | B4: 10 | C4: 100 | D4: 1000 | E4: 10000 | F4: 100000 | G4: 1000000 | I4: Swaps | J4: =AVERAGE(B6,B12,B18,B24,B30,B36,B42,B48,B54,B60) -> 9 | K4: =AVERAGE(C6,C12,C18,C24,C30,C36,C42,C48,C54,C60) -> 99 | L4: =AVERAGE(D6,D12,D18,D24,D30,D36,D42,D48,D54,D60) -> 999 | M4: =AVERAGE(E6,E12,E18,E24,E30,E36,E42,E48,E54,E60) -> 9999 | N4: =AVERAGE(F6,F12,F18,F24,F30,F36,F42,F48,F54,F60) -> 99999 | O4: =AVERAGE(G6,G12,G18,G24,G30,G36,G42,G48,G54,G60) -> 999999
A5: Miliseconds | B5: 1 | C5: 0 | D5: 15 | E5: 431 | F5: 45644 | G5: 1419571 | I5: Comparisons | J5: =AVERAGE(D7,B13,B19,B25,B31,B37,B43,B49,B55,B61) -> 49990.5 | K5: =AVERAGE(E7,C13,C19,C25,C31,C37,C43,C49,C55,C61) -> 5003955 | L5: =AVERAGE(F7,D13,D19,D25,D31,D37,D43,D49,D55,D61) -> 500444550 | M5: =AVERAGE(G7,E13,E19,E25,E31,E37,E43,E49,E55,E61) -> 50044945500 | N5: =AVERAGE(F7,P10,F13,F19,F25,F31,F37,F43,F49,F55,F61) -> 4999950000 | O5: =AVERAGE(InsertionSort!A7,G13,G19,G25,G31,G37,G43,G49,G55,G61) -> 499999500000
A6: Swaps | B6: 9 | C6: 99 | D6: 999 | E6: 9999 | F6: 99999 | G6: 999999
A7: Comparisons | B7: 45 | C7: 4950 | D7: 499500 | E7: 49995000 | F7: 4999950000 | G7: 499999500000
A9: Trial 2
A10: Number List Size | B10: 10 | C10: 100 | D10: 1000 | E10: 10000 | F10: 100000 | G10: 1000000
A11: Miliseconds | B11: 1 | C11: 0 | D11: 16 | E11: 393 | F11: 42860 | G11: 1351329
A12: Swaps | B12: 9 | C12: 99 | D12: 999 | E12: 9999 | F12: 99999 | G12: 999999
A13: Comparisons | B13: 45 | C13: 4950 | D13: 499500 | E13: 49995000 | F13: 4999950000 | G13: 499999500000
A15: Trial 3
A16: Number List Size | B16: 10 | C16: 100 | D16: 1000 | E16: 10000 | F16: 100000 | G16: 1000000
A17: Miliseconds | B17: 1 | C17: 3 | D17: 47 | E17: 348 | F17: 30688 | G17: 1188076
A18: Swaps | B18: 9 | C18: 99 | D18: 999 | E18: 9999 | F18: 99999 | G18: 999999
A19: Comparisons | B19: 45 | C19: 4950 | D19: 499500 | E19: 49995000 | F19: 4999950000 | G19: 499999500000
A21: Trial 4
A22: Number List Size | B22: 10 | C22: 100 | D22: 1000 | E22: 10000 | F22: 100000 | G22: 1000000
A23: Miliseconds | B23: 1 | C23: 8 | D23: 50 | E23: 474 | F23: 95739 | G23: 1107540
A24: Swaps | B24: 9 | C24: 99 | D24: 999 | E24: 9999 | F24: 99999 | G24: 999999 | I24: WORST RUN (Trial 4)
A25: Comparisons | B25: 45 | C25: 4950 | D25: 499500 | E25: 49995000 | F25: 4999950000 | G25: 499999500000 | I25: Number List Size | J25: 10 | K25: 100 | L25: 1000 | M25: 10000 | N25: 100000 | O25: 1000000
I26: Miliseconds | J26: 1 | K26: 8 | L26: 50 | M26: 474 | N26: 95739 | O26: 1107540
A27: Trial 5 | I27: Swaps | J27: 9 | K27: 99 | L27: 999 | M27: 9999 | N27: 99999 | O27: 999999
A28: Number List Size | B28: 10 | C28: 100 | D28: 1000 | E28: 10000 | F28: 100000 | G28: 1000000 | I28: Comparisons | J28: 45 | K28: 4950 | L28: 499500 | M28: 49995000 | N28: 4999950000 | O28: 499999500000
A29: Miliseconds | B29: 0 | C29: 1 | D29: 32 | E29: 501 | F29: 92559 | G29: 1146544
A30: Swaps | B30: 9 | C30: 99 | D30: 999 | E30: 9999 | F30: 99999 | G30: 999999
A31: Comparisons | B31: 45 | C31: 4950 | D31: 499500 | E31: 49995000 | F31: 4999950000 | G31: 499999500000
A33: Trial 6
A34: Number List Size | B34: 10 | C34: 100 | D34: 1000 | E34: 10000 | F34: 100000 | G34: 1000000
A35: Miliseconds | B35: 0 | C35: 0 | D35: 17 | E35: 383 | F35: 40043 | G35: 1262332
A36: Swaps | B36: 9 | C36: 99 | D36: 999 | E36: 9999 | F36: 99999 | G36: 999999
A37: Comparisons | B37: 45 | C37: 4950 | D37: 499500 | E37: 49995000 | F37: 4999950000 | G37: 499999500000
A39: Trial 7
A40: Number List Size | B40: 10 | C40: 100 | D40: 1000 | E40: 10000 | F40: 100000 | G40: 1000000
A41: Miliseconds | B41: 2 | C41: 2 | D41: 20 | E41: 360 | F41: 53114 | G41: 3319568
A42: Swaps | B42: 9 | C42: 99 | D42: 999 | E42: 9999 | F42: 99999 | G42: 999999
A43: Comparisons | B43: 45 | C43: 4950 | D43: 499500 | E43: 49995000 | F43: 4999950000 | G43: 499999500000
A45: Trial 8
A46: Number List Size | B46: 10 | C46: 100 | D46: 1000 | E46: 10000 | F46: 100000 | G46: 1000000
...

Sheet InsertionSort
A1: Insertion Sort Analysis Tables | I1: AVERAGE
I2: Number List Size | J2: 10 | K2: 100 | L2: 1000 | M2: 10000 | N2: 100000 | O2: 1000000
A3: Trial 1 | I3: Miliseconds | J3: =AVERAGE(InsertionSort!B5,InsertionSort!B11,InsertionSort!B17,InsertionSort!B23,InsertionSort!B29,InsertionSort!B35,InsertionSort!B41,InsertionSort!B47,InsertionSort!B53,InsertionSort!B59) -> 1.2 | K3: =AVERAGE(InsertionSort!C5,InsertionSort!C11,InsertionSort!C17,InsertionSort!C23,InsertionSort!C29,InsertionSort!C35,InsertionSort!C41,InsertionSort!C47,InsertionSort!C53,InsertionSort!C59) -> 0.3 | L3: =AVERAGE(InsertionSort!D5,InsertionSort!D11,InsertionSort!D17,InsertionSort!D23,InsertionSort!D29,InsertionSort!D35,InsertionSort!D41,InsertionSort!D47,InsertionSort!D53,InsertionSort!D59) -> 42.1 | M3: =AVERAGE(InsertionSort!E5,InsertionSort!E11,InsertionSort!E17,InsertionSort!E23,InsertionSort!E29,InsertionSort!E35,InsertionSort!E41,InsertionSort!E47,InsertionSort!E53,InsertionSort!E59) -> 777.7 | N3: =AVERAGE(InsertionSort!F5,InsertionSort!F11,InsertionSort!F17,InsertionSort!F23,InsertionSort!F29,InsertionSort!F35,InsertionSort!F41,InsertionSort!F47,InsertionSort!F53,InsertionSort!F59) -> 34517.1 | O3: =AVERAGE(InsertionSort!G5,InsertionSort!G11,InsertionSort!G17,InsertionSort!G23,InsertionSort!G29,InsertionSort!G35,InsertionSort!G41,InsertionSort!G47,InsertionSort!G53,InsertionSort!G59) -> 3076937.1
A4: Number List Size | B4: 10 | C4: 100 | D4: 1000 | E4: 10000 | F4: 100000 | G4: 1000000 | I4: Swaps | J4: =AVERAGE(InsertionSort!B6,InsertionSort!B12,InsertionSort!B18,InsertionSort!B24,InsertionSort!B30,InsertionSort!B36,InsertionSort!B42,InsertionSort!B48,InsertionSort!B54,InsertionSort!B60) -> 21.1 | K4: =AVERAGE(InsertionSort!C6,InsertionSort!C12,InsertionSort!C18,InsertionSort!C24,InsertionSort!C30,InsertionSort!C36,InsertionSort!C42,InsertionSort!C48,InsertionSort!C54,InsertionSort!C60) -> 2465.5 | L4: =AVERAGE(InsertionSort!D6,InsertionSort!D12,InsertionSort!D18,InsertionSort!D24,InsertionSort!D30,InsertionSort!D36,InsertionSort!D42,InsertionSort!D48,InsertionSort!D54,InsertionSort!D60) -> 2698921.3 | M4: =AVERAGE(InsertionSort!E6,InsertionSort!E12,InsertionSort!E18,InsertionSort!E24,InsertionSort!E30,InsertionSort!E36,InsertionSort!E42,InsertionSort!E48,InsertionSort!E54,InsertionSort!E60) -> 22747974 | N4: =AVERAGE(InsertionSort!F6,InsertionSort!F12,InsertionSort!F18,InsertionSort!F24,InsertionSort!F30,InsertionSort!F36,InsertionSort!F42,InsertionSort!F48,InsertionSort!F54,InsertionSort!F60) -> 2.4702546e+09 | O4: =AVERAGE(InsertionSort!G6,InsertionSort!G12,InsertionSort!G18,InsertionSort!G24,InsertionSort!G30,InsertionSort!G36,InsertionSort!G42,InsertionSort!G48,InsertionSort!G54,InsertionSort!G60) -> 2.4750073e+11
A5: Miliseconds | B5: 1 | C5: 0 | D5: 11 | E5: 412 | F5: 8782 | G5: 4885045 | I5: Comparisons | J5: =AVERAGE(InsertionSort!D7,InsertionSort!B13,InsertionSort!B19,InsertionSort!B25,InsertionSort!B31,InsertionSort!B37,InsertionSort!B43,InsertionSort!B49,InsertionSort!B55,InsertionSort!B61) -> 25029.2 | K5: =AVERAGE(InsertionSort!E7,InsertionSort!C13,InsertionSort!C19,InsertionSort!C25,InsertionSort!C31,InsertionSort!C37,InsertionSort!C43,InsertionSort!C49,InsertionSort!C55,InsertionSort!C61) -> 2488980.9 | L5: =AVERAGE(InsertionSort!F7,InsertionSort!D13,InsertionSort!D19,InsertionSort!D25,InsertionSort!D31,InsertionSort!D37,InsertionSort!D43,InsertionSort!D49,InsertionSort!D55,InsertionSort!D61) -> 2.4832865e+08 | M5: =AVERAGE(InsertionSort!G7,InsertionSort!E13,InsertionSort!E19,InsertionSort!E25,InsertionSort!E31,InsertionSort!E37,InsertionSort!E43,InsertionSort!E49,InsertionSort!E55,InsertionSort!E61) -> 2.4762037e+10 | N5: =AVERAGE(F7,InsertionSort!F13,InsertionSort!F19,InsertionSort!F25,InsertionSort!F31,InsertionSort!F37,InsertionSort!F43,InsertionSort!F49,InsertionSort!F55,InsertionSort!F61) -> 2.4767323e+09 | O5: =AVERAGE(MergeSort!A7,InsertionSort!G13,InsertionSort!G19,InsertionSort!G25,InsertionSort!G31,InsertionSort!G37,InsertionSort!G43,InsertionSort!G47,InsertionSort!G55,InsertionSort!G61) -> 2.1998311e+11
A6: Swaps | B6: 20 | C6: 2535 | D6: 252360 | E6: 24576245 | F6: 2463898384 | G6: 247419578087
A7: Comparisons | B7: 26 | C7: 2552 | D7: 250099 | E7: 24867994 | F7: 2481059667 | G7: 247418578088
A9: Trial 2
A10: Number List Size | B10: 10 | C10: 100 | D10: 1000 | E10: 10000 | F10: 100000 | G10: 1000000
A11: Miliseconds | B11: 1 | C11: 0 | D11: 17 | E11: 638 | F11: 43619 | G11: 1042435
A12: Swaps | B12: 16 | C12: 2575 | D12: 24745920 | E12: 4745920 | F12: 2470485380 | G12: 247336863577
A13: Comparisons | B13: 17 | C13: 2569 | D13: 243489 | E13: 24455437 | F13: 2476388265 | G13: 247335863578
A15: Trial 3
A16: Number List Size | B16: 10 | C16: 100 | D16: 1000 | E16: 10000 | F16: 100000 | G16: 1000000
A17: Miliseconds | B17: 1 | C17: 2 | D17: 68 | E17: 913 | F17: 19219 | G17: 3743662
A18: Swaps | B18: 29 | C18: 2217 | D18: 251647 | E18: 24857018 | F18: 2478976078 | G18: 247181371030
A19: Comparisons | B19: 19 | C19: 2152 | D19: 243335 | E19: 24767402 | F19: 2469520418 | G19: 247180371031
A21: Trial 4
A22: Number List Size | B22: 10 | C22: 100 | D22: 1000 | E22: 10000 | F22: 100000 | G22: 1000000
A23: Miliseconds | B23: 2 | C23: 0 | D23: 56 | E23: 803 | F23: 22949 | G23: 3748545
A24: Swaps | B24: 14 | C24: 2553 | D24: 253151 | E24: 24795077 | F24: 2475410164 | G24: 247731469847 | I24: WORST RUN (Trial 3)
A25: Comparisons | B25: 24 | C25: 2539 | D25: 254169 | E25: 24695872 | F25: 2479758471 | G25: 247730469848 | I25: Number List Size | J25: 10 | K25: 100 | L25: 1000 | M25: 10000 | N25: 100000 | O25: 1000000
I26: Miliseconds | J26: 1 | K26: 2 | L26: 68 | M26: 913 | N26: 19219 | O26: 3743662
A27: Trial 5 | I27: Swaps | J27: 29 | K27: 2217 | L27: 251647 | M27: 24857018 | N27: 2478976078 | O27: 247181371030
A28: Number List Size | B28: 10 | C28: 100 | D28: 1000 | E28: 10000 | F28: 100000 | G28: 1000000 | I28: Comparisons | J28: 19 | K28: 2152 | L28: 243335 | M28: 24767402 | N28: 2469520418 | O28: 247180371031
A29: Miliseconds | B29: 0 | C29: 0 | D29: 66 | E29: 861 | F29: 22543 | G29: 3748545
A30: Swaps | B30: 13 | C30: 2459 | D30: 248725 | E30: 24906899 | F30: 2475256811 | G30: 247731469847
A31: Comparisons | B31: 24 | C31: 2539 | D31: 254169 | E31: 24695872 | F31: 2479758471 | G31: 247730469848
A33: Trial 6
A34: Number List Size | B34: 10 | C34: 100 | D34: 1000 | E34: 10000 | F34: 100000 | G34: 1000000
A35: Miliseconds | B35: 1 | C35: 1 | D35: 12 | E35: 403 | F35: 37163 | G35: 4043896
A36: Swaps | B36: 18 | C36: 2218 | D36: 247729 | E36: 24419431 | F36: 2461791067 | G36: 247514635753
A37: Comparisons | B37: 25 | C37: 2755 | D37: 251596 | E37: 24444026 | F37: 2481434012 | G37: 247513635754
A39: Trial 7
A40: Number List Size | B40: 10 | C40: 100 | D40: 1000 | E40: 10000 | F40: 100000 | G40: 1000000
A41: Miliseconds | B41: 3 | C41: 0 | D41: 22 | E41: 719 | F41: 16625 | G41: 4048334
A42: Swaps | B42: 31 | C42: 2476 | D42: 243002 | E42: 24736817 | F42: 2468310878 | G42: 247504524397
A43: Comparisons | B43: 14 | C43: 2442 | D43: 257421 | E43: 24821732 | F43: 2481730261 | G43: 247503524398
A45: Trial 8
A46: Number List Size | B46: 10 | C46: 100 | D46: 1000 | E46: 10000 | F46: 100000 | G46: 1000000
...

Sheet MergeSort
A1: Merge Sort Analysis Tables | I1: AVERAGE
I2: Number List Size | J2: 10 | K2: 100 | L2: 1000 | M2: 10000 | N2: 100000 | O2: 1000000
A3: Trial 1 | I3: Miliseconds | J3: =AVERAGE(MergeSort!D5,MergeSort!B11,MergeSort!B17,MergeSort!B23,MergeSort!B29,MergeSort!B35,MergeSort!B41,MergeSort!B47,MergeSort!B53,MergeSort!B59) -> 1.8 | K3: =AVERAGE(MergeSort!C5,MergeSort!C11,MergeSort!C17,MergeSort!C23,MergeSort!C29,MergeSort!C35,MergeSort!C41,MergeSort!C47,MergeSort!C53,MergeSort!C59) -> 0.5 | L3: =AVERAGE(MergeSort!D5,MergeSort!D11,MergeSort!D17,MergeSort!D23,MergeSort!D29,MergeSort!D35,MergeSort!D41,MergeSort!D47,MergeSort!D53,MergeSort!D59) -> 5.4 | M3: =AVERAGE(MergeSort!E5,MergeSort!E11,MergeSort!E17,MergeSort!E23,MergeSort!E29,MergeSort!E35,MergeSort!E41,MergeSort!E47,MergeSort!E53,MergeSort!E59) -> 19.6 | N3: =AVERAGE(MergeSort!F5,MergeSort!F11,MergeSort!F17,MergeSort!F23,MergeSort!F29,MergeSort!F35,MergeSort!F41,MergeSort!F47,MergeSort!F53,MergeSort!F59) -> 131.1 | O3: =AVERAGE(MergeSort!G5,MergeSort!G11,MergeSort!G17,MergeSort!G23,MergeSort!G29,MergeSort!G35,MergeSort!G41,MergeSort!G47,MergeSort!G53,MergeSort!G59) -> 828.8
A4: Number List Size | B4: 10 | C4: 100 | D4: 1000 | E4: 10000 | F4: 100000 | G4: 1000000 | I4: Swaps | J4: =AVERAGE(MergeSort!D6,MergeSort!B12,MergeSort!B18,MergeSort!B24,MergeSort!B30,MergeSort!B36,MergeSort!B42,MergeSort!B48,MergeSort!B54,MergeSort!B60) -> 455 | K4: =AVERAGE(MergeSort!C6,MergeSort!C12,MergeSort!C18,MergeSort!C24,MergeSort!C30,MergeSort!C36,MergeSort!C42,MergeSort!C48,MergeSort!C54,MergeSort!C60) -> 281.2 | L4: =AVERAGE(MergeSort!D6,MergeSort!D12,MergeSort!D18,MergeSort!D24,MergeSort!D30,MergeSort!D36,MergeSort!D42,MergeSort!D48,MergeSort!D54,MergeSort!D60) -> 4391.6 | M4: =AVERAGE(MergeSort!E6,MergeSort!E12,MergeSort!E18,MergeSort!E24,MergeSort!E30,MergeSort!E36,MergeSort!E42,MergeSort!E48,MergeSort!E54,MergeSort!E60) -> 61355.6 | N4: =AVERAGE(MergeSort!F6,MergeSort!F12,MergeSort!F18,MergeSort!F24,MergeSort!F30,MergeSort!F36,MergeSort!F42,MergeSort!F48,MergeSort!F54,MergeSort!F60) -> 776437.3 | O4: =AVERAGE(MergeSort!G6,MergeSort!G12,MergeSort!G18,MergeSort!G24,MergeSort!G30,MergeSort!G36,MergeSort!G42,MergeSort!G48,MergeSort!G54,MergeSort!G60) -> 9395200.6
A5: Miliseconds | B5: 5 | C5: 1 | D5: 7 | E5: 21 | F5: 278 | G5: 937 | I5: Comparisons | J5: =AVERAGE(MergeSort!D7,MergeSort!B13,MergeSort!B19,MergeSort!B25,MergeSort!B31,MergeSort!B37,MergeSort!B43,MergeSort!B49,MergeSort!B55,MergeSort!B61) -> 894.1 | K5: =AVERAGE(MergeSort!E7,MergeSort!C13,MergeSort!C19,MergeSort!C25,MergeSort!C31,MergeSort!C37,MergeSort!C43,MergeSort!C49,MergeSort!C55,MergeSort!C61) -> 12530.5 | L5: =AVERAGE(MergeSort!F7,MergeSort!D13,MergeSort!D19,MergeSort!D25,MergeSort!D31,MergeSort!D37,MergeSort!D43,MergeSort!D49,MergeSort!D55,MergeSort!D61) -> 161459.7 | M5: =AVERAGE(MergeSort!G7,MergeSort!E13,MergeSort!E19,MergeSort!E25,MergeSort!E31,MergeSort!E37,MergeSort!E43,MergeSort!E49,MergeSort!E55,MergeSort!E61) -> 1975890.2 | N5: =AVERAGE(F7,MergeSort!F13,MergeSort!F19,MergeSort!F25,MergeSort!F31,MergeSort!F37,MergeSort!F43,MergeSort!F49,MergeSort!F55,MergeSort!F61) -> 1536354.4 | O5: =AVERAGE(QuickSort!A7,MergeSort!G13,MergeSort!G19,MergeSort!G25,MergeSort!G31,MergeSort!G37,MergeSort!G43,MergeSort!G49,MergeSort!G55,MergeSort!G61) -> 18674383
A6: Swaps | B6: 16 | C6: 285 | D6: 4440 | E6: 61348 | F6: 776376 | G6: 9394501
A7: Comparisons | B7: 25 | C7: 544 | D7: 8734 | E7: 120429 | F7: 1536275 | G7: 18674613
A9: Trial 2
A10: Number List Size | B10: 10 | C10: 100 | D10: 1000 | E10: 10000 | F10: 100000 | G10: 1000000
A11: Miliseconds | B11: 1 | C11: 0 | D11: 4 | E11: 8 | F11: 107 | G11: 895
A12: Swaps | B12: 14 | C12: 281 | D12: 4453 | E12: 61288 | F12: 776444 | G12: 9396123
A13: Comparisons | B13: 24 | C13: 549 | D13: 8716 | E13: 120456 | F13: 1536445 | G13: 18674973
A15: Trial 3
A16: Number List Size | B16: 10 | C16: 100 | D16: 1000 | E16: 10000 | F16: 100000 | G16: 1000000
A17: Miliseconds | B17: 1 | C17: 1 | D17: 9 | E17: 8 | F17: 126 | G17: 997
A18: Swaps | B18: 9 | C18: 272 | D18: 4334 | E18: 61451 | F18: 776058 | G18: 9395628
A19: Comparisons | B19: 22 | C19: 540 | D19: 8677 | E19: 120490 | F19: 1536450 | G19: 18674642
A21: Trial 4
A22: Number List Size | B22: 10 | C22: 100 | D22: 1000 | E22: 10000 | F22: 100000 | G22: 1000000
A23: Miliseconds | B23: 1 | C23: 1 | D23: 6 | E23: 19 | F23: 99 | G23: 747
A24: Swaps | B24: 13 | C24: 288 | D24: 4419 | E24: 61407 | F24: 776729 | G24: 9395345 | I24: WORST RUN (Trial 1)
A25: Comparisons | B25: 24 | C25: 538 | D25: 8720 | E25: 120516 | F25: 1536624 | G25: 18673708 | I25: Number List Size | J25: 10 | K25: 100 | L25: 1000 | M25: 10000 | N25: 100000 | O25: 1000000
I26: Miliseconds | J26: 5 | K26: 1 | L26: 7 | M26: 21 | N26: 278 | O26: 937
A27: Trial 5 | I27: Swaps | J27: 16 | K27: 285 | L27: 4440 | M27: 61348 | N27: 776376 | O27: 9394501
A28: Number List Size | B28: 10 | C28: 100 | D28: 1000 | E28: 10000 | F28: 100000 | G28: 1000000 | I28: Comparisons | J28: 25 | K28: 544 | L28: 8734 | M28: 120429 | N28: 1536275 | O28: 18674613
A29: Miliseconds | B29: 2 | C29: 0 | D29: 4 | E29: 18 | F29: 85 | G29: 839
A30: Swaps | B30: 13 | C30: 289 | D30: 4392 | E30: 61230 | F30: 777102 | G30: 9396799
A31: Comparisons | B31: 22 | C31: 550 | D31: 8697 | E31: 120456 | F31: 1536570 | G31: 18675025
A33: Trial 6
A34: Number List Size | B34: 10 | C34: 100 | D34: 1000 | E34: 10000 | F34: 100000 | G34: 1000000
A35: Miliseconds | B35: 2 | C35: 0 | D35: 7 | E35: 27 | F35: 88 | G35: 706
A36: Swaps | B36: 13 | C36: 273 | D36: 4336 | E36: 61243 | F36: 776110 | G36: 9394427
A37: Comparisons | B37: 24 | C37: 535 | D37: 8688 | E37: 120324 | F37: 1536364 | G37: 18674380
A39: Trial 7
A40: Number List Size | B40: 10 | C40: 100 | D40: 1000 | E40: 10000 | F40: 100000 | G40: 1000000
A41: Miliseconds | B41: 1 | C41: 0 | D41: 4 | E41: 15 | F41: 93 | G41: 906
A42: Swaps | B42: 16 | C42: 283 | D42: 4381 | E42: 61225 | F42: 776621 | G42: 9395429
A43: Comparisons | B43: 24 | C43: 540 | D43: 8701 | E43: 120489 | F43: 1536255 | G43: 18674404
A45: Trial 8
A46: Number List Size | B46: 10 | C46: 100 | D46: 1000 | E46: 10000 | F46: 100000 | G46: 1000000
...

Sheet QuickSort
A1: Quick Sort Analysis Tables | I1: AVERAGE
I2: Number List Size | J2: 10 | K2: 100 | L2: 1000 | M2: 10000 | N2: 100000 | O2: 1000000
A3: Trial 1 | I3: Miliseconds | J3: =AVERAGE(QuickSort!B5,QuickSort!B11,QuickSort!B17,QuickSort!B23,QuickSort!B29,QuickSort!B35,QuickSort!B41,QuickSort!B47,QuickSort!B53,QuickSort!B59) -> 0 | K3: =AVERAGE(QuickSort!C5,QuickSort!C11,QuickSort!C17,QuickSort!C23,QuickSort!C29,QuickSort!C35,QuickSort!C41,QuickSort!C47,QuickSort!C53,QuickSort!C59) -> 0.3 | L3: =AVERAGE(QuickSort!D5,QuickSort!D11,QuickSort!D17,QuickSort!D23,QuickSort!D29,QuickSort!D35,QuickSort!D41,QuickSort!D47,QuickSort!D53,QuickSort!D59) -> 2.3 | M3: =AVERAGE(QuickSort!E5,QuickSort!E11,QuickSort!E17,QuickSort!E23,QuickSort!E29,QuickSort!E35,QuickSort!E41,QuickSort!E47,QuickSort!E53,QuickSort!E59) -> 7.1 | N3: =AVERAGE(QuickSort!F5,QuickSort!F11,QuickSort!F17,QuickSort!F23,QuickSort!F29,QuickSort!F35,QuickSort!F41,QuickSort!F47,QuickSort!F53,QuickSort!F59) -> 32.5 | O3: =AVERAGE(QuickSort!G5,QuickSort!G11,QuickSort!G17,QuickSort!G23,QuickSort!G29,QuickSort!G35,QuickSort!G41,QuickSort!G47,QuickSort!G53,QuickSort!G59) -> 199
A4: Number List Size | B4: 10 | C4: 100 | D4: 1000 | E4: 10000 | F4: 100000 | G4: 1000000 | I4: Swaps | J4: =AVERAGE(QuickSort!B6,QuickSort!B12,QuickSort!B18,QuickSort!B24,QuickSort!B30,QuickSort!B36,QuickSort!B42,QuickSort!B48,QuickSort!B54,QuickSort!B60) -> 18.2 | K4: =AVERAGE(QuickSort!C6,QuickSort!C12,QuickSort!C18,QuickSort!C24,QuickSort!C30,QuickSort!C36,QuickSort!C42,QuickSort!C48,QuickSort!C54,QuickSort!C60) -> 403.3 | L4: =AVERAGE(QuickSort!D6,QuickSort!D12,QuickSort!D18,QuickSort!D24,QuickSort!D30,QuickSort!D36,QuickSort!D42,QuickSort!D48,QuickSort!D54,QuickSort!D60) -> 6169 | M4: =AVERAGE(QuickSort!E6,QuickSort!E12,QuickSort!E18,QuickSort!E24,QuickSort!E30,QuickSort!E36,QuickSort!E42,QuickSort!E48,QuickSort!E54,QuickSort!E60) -> 86020.4 | N4: =AVERAGE(QuickSort!F6,QuickSort!F12,QuickSort!F18,QuickSort!F24,QuickSort!F30,QuickSort!F36,QuickSort!F42,QuickSort!F48,QuickSort!F54,QuickSort!F60) -> 1108697.3 | O4: =AVERAGE(QuickSort!G6,QuickSort!G12,QuickSort!G18,QuickSort!G24,QuickSort!G30,QuickSort!G36,QuickSort!G42,QuickSort!G48,QuickSort!G54,QuickSort!G60) -> 13489906
A5: Miliseconds | B5: 0 | C5: 0 | D5: 2 | E5: 6 | F5: 17 | G5: 179 | I5: Comparisons | J5: =AVERAGE(QuickSort!D7,QuickSort!B13,QuickSort!B19,QuickSort!B25,QuickSort!B31,QuickSort!B37,QuickSort!B43,QuickSort!B49,QuickSort!B55,QuickSort!B61) -> 1171.1 | K5: =AVERAGE(QuickSort!E7,QuickSort!C13,QuickSort!C19,QuickSort!C25,QuickSort!C31,QuickSort!C37,QuickSort!C43,QuickSort!C49,QuickSort!C55,QuickSort!C61) -> 17243.5 | L5: =AVERAGE(QuickSort!F7,QuickSort!D13,QuickSort!D19,QuickSort!D25,QuickSort!D31,QuickSort!D37,QuickSort!D43,QuickSort!D49,QuickSort!D55,QuickSort!D61) -> 217247.5 | M5: =AVERAGE(QuickSort!G7,QuickSort!E13,QuickSort!E19,QuickSort!E25,QuickSort!E31,QuickSort!E37,QuickSort!E43,QuickSort!E49,QuickSort!E55,QuickSort!E61) -> 2856761.2 | N5: =AVERAGE(F7,QuickSort!F13,QuickSort!F19,QuickSort!F25,QuickSort!F31,QuickSort!F37,QuickSort!F43,QuickSort!F49,QuickSort!F55,QuickSort!F61) -> 2144724.4 | O5: =AVERAGE(HeapSort!A7,QuickSort!G13,QuickSort!G19,QuickSort!G25,QuickSort!G31,QuickSort!G37,QuickSort!G43,QuickSort!G49,QuickSort!G55,QuickSort!G61) -> 25978646
A6: Swaps | B6: 15 | C6: 484 | D6: 6120 | E6: 79820 | F6: 1004604 | G6: 13965627
A7: Comparisons | B7: 35 | C7: 729 | D7: 11444 | E7: 166126 | F7: 2067720 | G7: 27103704
A9: Trial 2
A10: Number List Size | B10: 10 | C10: 100 | D10: 1000 | E10: 10000 | F10: 100000 | G10: 1000000
A11: Miliseconds | B11: 0 | C11: 0 | D11: 5 | E11: 5 | F11: 23 | G11: 316
A12: Swaps | B12: 24 | C12: 391 | D12: 6170 | E12: 84157 | F12: 1041140 | G12: 12845555
A13: Comparisons | B13: 32 | C13: 711 | D13: 12182 | E13: 164242 | F13: 2126401 | G13: 25543141
A15: Trial 3
A16: Number List Size | B16: 10 | C16: 100 | D16: 1000 | E16: 10000 | F16: 100000 | G16: 1000000
A17: Miliseconds | B17: 0 | C17: 0 | D17: 2 | E17: 7 | F17: 53 | G17: 217
A18: Swaps | B18: 16 | C18: 395 | D18: 6239 | E18: 97067 | F18: 1177214 | G18: 14696689
A19: Comparisons | B19: 27 | C19: 714 | D19: 12289 | E19: 168076 | F19: 2381653 | G19: 27353376
A21: Trial 4
A22: Number List Size | B22: 10 | C22: 100 | D22: 1000 | E22: 10000 | F22: 100000 | G22: 1000000
A23: Miliseconds | B23: 0 | C23: 1 | D23: 2 | E23: 10 | F23: 17 | G23: 177
A24: Swaps | B24: 19 | C24: 342 | D24: 7663 | E24: 81216 | F24: 1068880 | G24: 12938235 | I24: WORST RUN (Trial 2)
A25: Comparisons | B25: 29 | C25: 743 | D25: 12972 | E25: 155290 | F25: 2055560 | G25: 25669084 | I25: Number List Size | J25: 10 | K25: 100 | L25: 1000 | M25: 10000 | N25: 100000 | O25: 1000000
I26: Miliseconds | J26: 0 | K26: 0 | L26: 5 | M26: 5 | N26: 23 | O26: 316
A27: Trial 5 | I27: Swaps | J27: 24 | K27: 391 | L27: 6170 | M27: 84157 | N27: 1041140 | O27: 12845555
A28: Number List Size | B28: 10 | C28: 100 | D28: 1000 | E28: 10000 | F28: 100000 | G28: 1000000 | I28: Comparisons | J28: 32 | K28: 711 | L28: 12182 | M28: 164242 | N28: 2126401 | O28: 25543141
A29: Miliseconds | B29: 0 | C29: 0 | D29: 5 | E29: 7 | F29: 58 | G29: 176
A30: Swaps | B30: 14 | C30: 401 | D30: 5972 | E30: 95383 | F30: 1092903 | G30: 12962703
A31: Comparisons | B31: 27 | C31: 682 | D31: 10748 | E31: 163090 | F31: 2080880 | G31: 26579544
A33: Trial 6
A34: Number List Size | B34: 10 | C34: 100 | D34: 1000 | E34: 10000 | F34: 100000 | G34: 1000000
A35: Miliseconds | B35: 0 | C35: 1 | D35: 1 | E35: 6 | F35: 44 | G35: 188
A36: Swaps | B36: 24 | C36: 378 | D36: 6662 | E36: 88726 | F36: 1098131 | G36: 13562090
A37: Comparisons | B37: 30 | C37: 664 | D37: 11905 | E37: 156305 | F37: 2113616 | G37: 25913526
A39: Trial 7
A40: Number List Size | B40: 10 | C40: 100 | D40: 1000 | E40: 10000 | F40: 100000 | G40: 1000000
A41: Miliseconds | B41: 0 | C41: 0 | D41: 2 | E41: 17 | F41: 58 | G41: 172
A42: Swaps | B42: 12 | C42: 357 | D42: 5909 | E42: 90377 | F42: 1073469 | G42: 13131919
A43: Comparisons | B43: 33 | C43: 685 | D43: 11564 | E43: 168872 | F43: 2168409 | G43: 24919643
A45: Trial 8
A46: Number List Size | B46: 10 | C46: 100 | D46: 1000 | E46: 10000 | F46: 100000 | G46: 1000000
...

Sheet HeapSort
A1: Heap Sort Analysis Tables | I1: AVERAGE
I2: Number List Size | J2: 10 | K2: 100 | L2: 1000 | M2: 10000 | N2: 100000 | O2: 1000000
A3: Trial 1 | I3: Miliseconds | J3: =AVERAGE(HeapSort!B5,HeapSort!B11,HeapSort!B17,HeapSort!B23,HeapSort!B29,HeapSort!B35,HeapSort!B41,HeapSort!B47,HeapSort!B53,HeapSort!B59) -> 0 | K3: =AVERAGE(HeapSort!C5,HeapSort!C11,HeapSort!C17,HeapSort!C23,HeapSort!C29,HeapSort!C35,HeapSort!C41,HeapSort!C47,HeapSort!C53,HeapSort!C59) -> 0.8 | L3: =AVERAGE(HeapSort!D5,HeapSort!E11,HeapSort!D17,HeapSort!D23,HeapSort!D29,HeapSort!D35,HeapSort!D41,HeapSort!D47,HeapSort!D53,HeapSort!D59) -> 1.8 | M3: =AVERAGE(HeapSort!E5,HeapSort!F11,HeapSort!E17,HeapSort!E23,HeapSort!E29,HeapSort!E35,HeapSort!E41,HeapSort!E47,HeapSort!E53,HeapSort!E59) -> 9.8 | N3: =AVERAGE(HeapSort!F5,HeapSort!G11,HeapSort!F17,HeapSort!F23,HeapSort!F29,HeapSort!F35,HeapSort!F41,HeapSort!F47,HeapSort!F53,HeapSort!F59) -> 58.2 | O3: =AVERAGE(HeapSort!G5,HeapSort!G11,HeapSort!G17,HeapSort!G23,HeapSort!G29,HeapSort!G35,HeapSort!G41,HeapSort!G47,HeapSort!G53,HeapSort!G59) -> 341.6
A4: Number List Size | B4: 10 | C4: 100 | D4: 1000 | E4: 10000 | F4: 100000 | G4: 1000000 | I4: Swaps | J4: =AVERAGE(HeapSort!B6,HeapSort!B12,HeapSort!B18,HeapSort!B24,HeapSort!B30,HeapSort!B36,HeapSort!B42,HeapSort!B48,HeapSort!B54,HeapSort!B60) -> 27.8 | K4: =AVERAGE(HeapSort!C6,HeapSort!C12,HeapSort!C18,HeapSort!C24,HeapSort!C30,HeapSort!C36,HeapSort!C42,HeapSort!C48,HeapSort!C54,HeapSort!C60) -> 581.7 | L4: =AVERAGE(HeapSort!D6,HeapSort!E12,HeapSort!D18,HeapSort!D24,HeapSort!D30,HeapSort!D36,HeapSort!D42,HeapSort!D48,HeapSort!D54,HeapSort!D60) -> 20658.3 | M4: =AVERAGE(HeapSort!E6,HeapSort!F12,HeapSort!E18,HeapSort!E24,HeapSort!E30,HeapSort!E36,HeapSort!E42,HeapSort!E48,HeapSort!E54,HeapSort!E60) -> 269727 | N4: =AVERAGE(HeapSort!F6,HeapSort!G12,HeapSort!F18,HeapSort!F24,HeapSort!F30,HeapSort!F36,HeapSort!F42,HeapSort!F48,HeapSort!F54,HeapSort!F60) -> 3326971.7 | O4: =AVERAGE(HeapSort!G6,HeapSort!G12,HeapSort!G18,HeapSort!G24,HeapSort!G30,HeapSort!G36,HeapSort!G42,HeapSort!G48,HeapSort!G54,HeapSort!G60) -> 19073786
A5: Miliseconds | B5: 0 | C5: 1 | D5: 5 | E5: 8 | F5: 39 | G5: 580 | I5: Comparisons | J5: =AVERAGE(HeapSort!D7,HeapSort!B13,HeapSort!B19,HeapSort!B25,HeapSort!B31,HeapSort!B37,HeapSort!B43,HeapSort!B49,HeapSort!B55,HeapSort!B61) -> 1975.6 | K5: =AVERAGE(HeapSort!E7,HeapSort!C13,HeapSort!C19,HeapSort!C25,HeapSort!C31,HeapSort!C37,HeapSort!C43,HeapSort!C49,HeapSort!C55,HeapSort!C61) -> 27036 | L5: =AVERAGE(HeapSort!F7,HeapSort!D13,HeapSort!D19,HeapSort!D25,HeapSort!D31,HeapSort!D37,HeapSort!D43,HeapSort!D49,HeapSort!D55,HeapSort!D61) -> 342833.2 | M5: =AVERAGE(HeapSort!G7,HeapSort!E13,HeapSort!E19,HeapSort!E25,HeapSort!E31,HeapSort!E37,HeapSort!E43,HeapSort!E49,HeapSort!E55,HeapSort!E61) -> 4147652.8 | N5: =AVERAGE(HeapSort!F7,HeapSort!F13,HeapSort!F19,HeapSort!F25,HeapSort!F31,HeapSort!F37,HeapSort!F43,HeapSort!F49,HeapSort!F55,HeapSort!F61) -> 3254772.8 | O5: =AVERAGE(HeapSort!G7,HeapSort!G13,HeapSort!G19,HeapSort!G25,HeapSort!G31,HeapSort!G37,HeapSort!G43,HeapSort!G49,HeapSort!G55,HeapSort!G61) -> 39147573
A6: Swaps | B6: 27 | C6: 578 | D6: 9082 | E6: 124491 | F6: 1577625 | G6: 19073125
A7: Comparisons | B7: 64 | C7: 1256 | D7: 19164 | E7: 258982 | F7: 3255250 | G7: 39146250
A9: Trial 2
A10: Number List Size | B10: 10 | C10: 100 | D10: 1000 | E10: 10000 | F10: 100000 | G10: 1000000
A11: Miliseconds | B11: 0 | C11: 1 | D11: 1 | E11: 6 | F11: 32 | G11: 297
A12: Swaps | B12: 28 | C12: 587 | D12: 9089 | E12: 124549 | F12: 1577189 | G12: 19073042
A13: Comparisons | B13: 66 | C13: 1274 | D13: 19178 | E13: 259098 | F13: 3254378 | G13: 39146084
A15: Trial 3
A16: Number List Size | B16: 10 | C16: 100 | D16: 1000 | E16: 10000 | F16: 100000 | G16: 1000000
A17: Miliseconds | B17: 0 | C17: 1 | D17: 0 | E17: 7 | F17: 33 | G17: 292
A18: Swaps | B18: 30 | C18: 568 | D18: 9126 | E18: 124363 | F18: 1577390 | G18: 19072314
A19: Comparisons | B19: 70 | C19: 1236 | D19: 19252 | E19: 258726 | F19: 3254780 | G19: 39144628
A21: Trial 4
A22: Number List Size | B22: 10 | C22: 100 | D22: 1000 | E22: 10000 | F22: 100000 | G22: 1000000
A23: Miliseconds | B23: 0 | C23: 0 | D23: 1 | E23: 5 | F23: 30 | G23: 296
A24: Swaps | B24: 28 | C24: 591 | D24: 9104 | E24: 124526 | F24: 1577138 | G24: 19073999
A25: Comparisons | B25: 66 | C25: 1282 | D25: 19208 | E25: 259052 | F25: 3254276 | G25: 39147998 | I25: WORST RUN (Trial 3)
I26: Number List Size | J26: 10 | K26: 100 | L26: 1000 | M26: 10000 | N26: 100000 | O26: 1000000
A27: Trial 5 | I27: Miliseconds | J27: 0 | K27: 1 | L27: 0 | M27: 7 | N27: 33 | O27: 292
A28: Number List Size | B28: 10 | C28: 100 | D28: 1000 | E28: 10000 | F28: 100000 | G28: 1000000 | I28: Swaps | J28: 30 | K28: 568 | L28: 9126 | M28: 124363 | N28: 1577390 | O28: 19072314
A29: Miliseconds | B29: 0 | C29: 0 | D29: 0 | E29: 7 | F29: 32 | G29: 323 | I29: Comparisons | J29: 70 | K29: 1236 | L29: 19252 | M29: 258726 | N29: 3254780 | O29: 39144628
A30: Swaps | B30: 28 | C30: 580 | D30: 9153 | E30: 124550 | F30: 1577586 | G30: 19074123
A31: Comparisons | B31: 66 | C31: 1260 | D31: 19306 | E31: 259100 | F31: 3255172 | G31: 39148246
A33: Trial 6
A34: Number List Size | B34: 10 | C34: 100 | D34: 1000 | E34: 10000 | F34: 100000 | G34: 1000000
A35: Miliseconds | B35: 0 | C35: 2 | D35: 2 | E35: 5 | F35: 29 | G35: 322
A36: Swaps | B36: 27 | C36: 571 | D36: 9122 | E36: 124534 | F36: 1577678 | G36: 19073821
A37: Comparisons | B37: 64 | C37: 1242 | D37: 19244 | E37: 259068 | F37: 3255356 | G37: 39147642
A39: Trial 7
A40: Number List Size | B40: 10 | C40: 100 | D40: 1000 | E40: 10000 | F40: 100000 | G40: 1000000
A41: Miliseconds | B41: 0 | C41: 0 | D41: 0 | E41: 8 | F41: 29 | G41: 322
A42: Swaps | B42: 27 | C42: 578 | D42: 9119 | E42: 124373 | F42: 1577376 | G42: 19074492
A43: Comparisons | B43: 64 | C43: 1256 | D43: 19238 | E43: 258746 | F43: 3254752 | G43: 39148984
A45: Trial 8
A46: Number List Size | B46: 10 | C46: 100 | D46: 1000 | E46: 10000 | F46: 100000 | G46: 1000000
...
